Workbook

Sheet Cover Page
B1: Financial Statement Analysis & Valuation of Larsen & Toubro Ltd.
A3: (Based on Financial Statements for FY2022–FY2026)
D19: PROJECT DETAILS
D20: Field | G20: Details
D21: Company | G21: Larsen & Toubro Ltd.
D22: Industry | G22: Engineering & Construction
D23: Analysis Period | G23: FY2022 - FY2026
D24: Currency | G24: Crores
D25: Data Source | G25: Screener.in & Annual Reports
D26: Valuation Method | G26: Discounted Cash Flow (DCF)
D27: Project Type | G27: Financial Statement Analysis & Valuation
D30: STUDENT INFORMATION
D31: Field | G31: Details
D32: Submitted By | G32: Pandya Harsh Priyank
D33: Enrollment No. | G33: 2506142250002
D34: Programme | G34: MBA in Finance with SAP
D35: University | G35: Parul University
D36: Academic Year | G36: 2026-27
D37: Guide | G37: Prayag Sir
D39: Financial Data used in this workbook has been compiled from publicly available sources and analysed for academic purposes only
C44: Prepared as a part of the MBA Financial Statement Analysis & Valuation Project

Sheet Raw Data
A1: Larsen & Toubro Ltd. – Raw Financial Data (₹ Crores)
A3: Particulars | B3: 44256 | C3: 44621 | D3: 44986 | E3: 45352 | F3: 45717 | G3: 46082
A5: PROFIT & LOSS
A6: Sales | B6: 135979.03 | C6: 156521.23 | D6: 183340.7 | E6: 221112.91 | F6: 255734.45 | G6: 285874.36
A7: Expenses | B7: 112518.79 | C7: 132207.34 | D7: 156174.68 | E7: 192354.79 | F7: 221307.55 | G7: 250463.66
A8: Operating Profit | B8: 23460.24 | C8: 24313.89 | D8: 27166.02 | E8: 28758.12 | F8: 34426.9 | G8: 35410.7
A9: Other Income | B9: 8111.25 | C9: 2364.01 | D9: 2890.7 | E9: 4953.49 | F9: 3197.85 | G9: 4985.8
A10: Depreciation | B10: 2904.21 | C10: 2947.95 | D10: 3502.25 | E10: 3682.33 | F10: 4121.18 | G10: 4364.75
A11: Interest | B11: 11749.58 | C11: 9234.98 | D11: 9445.44 | E11: 9512.17 | F11: 9924.78 | G11: 10055.94
A12: Profit before tax | B12: 16917.7 | C12: 14494.97 | D12: 17109.03 | E12: 20517.11 | F12: 23578.79 | G12: 25975.81
A13: Tax | B13: 4010.82 | C13: 4203.92 | D13: 4484.16 | E13: 4947.39 | F13: 5891.4 | G13: 6816.41
A14: Net profit | B14: 11582.93 | C14: 8669.33 | D14: 10470.72 | E14: 13059.11 | F14: 15037.11 | G14: 16083.99
A15: EPS | B15: 82.46426 | C15: 61.703416 | D15: 74.498186 | E15: 94.996072 | F15: 109.3449 | G15: 116.92345
A17: BALANCE SHEET
A18: Equity Share Capital | B18: 280.91 | C18: 281.01 | D18: 281.1 | E18: 274.93 | F18: 275.04 | G18: 275.13
A19: Reserves | B19: 75587.62 | C19: 82126.65 | D19: 89044.85 | E19: 86084.31 | F19: 97380.56 | G19: 109014.67
A20: Borrowings | B20: 134629.08 | C20: 125508.08 | D20: 120650.44 | E20: 116322.22 | F20: 132408.92 | G20: 125496.59
A21: Other Liabilities | B21: 99597.44 | C21: 111112.17 | D21: 119745.49 | E21: 136920.88 | F21: 149049.57 | G21: 217596.38
A22: Total | B22: 310095.05 | C22: 319027.91 | D22: 329721.88 | E22: 339602.34 | F22: 379114.09 | G22: 452382.77
A24: Net Block | B24: 44319.32 | C24: 42945.01 | D24: 42641 | E24: 42963.82 | F24: 44055.45 | G24: 30866.91
A25: Capital Work in Progress | B25: 500.39 | C25: 1249.55 | D25: 3065.57 | E25: 3045.01 | F25: 2588.68 | G25: 3310.95
A26: Investments | B26: 39626.63 | C26: 39395.18 | D26: 44798.31 | E26: 45647.82 | F26: 54805.27 | G26: 68376.79
A27: Other Assets | B27: 225648.71 | C27: 235438.17 | D27: 239217 | E27: 247945.69 | F27: 277664.69 | G27: 349828.12
A28: Total | B28: 310095.05 | C28: 319027.91 | D28: 329721.88 | E28: 339602.34 | F28: 379114.09 | G28: 452382.77
A30: Working Capital | B30: 126051.27 | C30: 124326 | D30: 119471.51 | E30: 111024.81 | F30: 128615.12 | G30: 132231.74
A31: Debtors | B31: 42229.78 | C31: 46139.32 | D31: 44731.53 | E31: 48770.95 | F31: 53713.68 | G31: 60461.26
... A38: Face value | B38: 2 | C38: 2 | D38: 2 | E38: 2 | F38: 2 | G38: 2
A40: CASH FLOW
A41: Cash from Operating Activity | B41: 23073.82 | C41: 19163.58 | D41: 22776.96 | E41: 18266.28 | F41: 9151.35 | G41: 16740.97
A42: Cash from Investing Activity | B42: -5750.49 | C42: -3585.38 | D42: -8048.02 | E42: 2178.89 | F42: -15479.47 | G42: -11380.3
A43: Cash from Financing Activity | B43: -15274.38 | C43: -15181.48 | D43: -11572.49 | E43: -25413.36 | F43: 6556.62 | G43: -2156.43
A44: Net Cash Flow | B44: 2048.95 | C44: 396.72 | D44: 3156.45 | E44: -4968.19 | F44: 228.5 | G44: 3204.24

Sheet Financial Ratios
A1: Financial Ratio Analysis of Larsen & Toubro Ltd. (FY 2022–FY 2026)
A3: Ratio | B3: Formula | C3: 44621 | D3: 44986 | E3: 45352 | F3: 45717 | G3: 46082 | H3: Interpretation
A4: PROFITABILITY RATIOS
A5: Operating Profit Margin (%) | B5: Operating Profit ÷ Sales | C5: ='Raw Data'!C8/'Raw Data'!C6 -> 0.15533925 | D5: ='Raw Data'!D8/'Raw Data'!D6 -> 0.14817234 | E5: ='Raw Data'!E8/'Raw Data'!E6 -> 0.13006079 | F5: ='Raw Data'!F8/'Raw Data'!F6 -> 0.13461972 | G5: ='Raw Data'!G8/'Raw Data'!G6 -> 0.12386805 | H5: Operating Profit Margin declined from 15.53% in FY2022 to 12.39% in FY2026, indicating that operating costs increased faster than sales over the period. Although the margin improved slightly in FY2025, it declined again in FY2026, suggesting some pressure on operating profitability.
A6: Net Profit Margin (%) | B6: Net Profit ÷ Sales | C6: ='Raw Data'!C14/'Raw Data'!C6 -> 0.055387566 | D6: ='Raw Data'!D14/'Raw Data'!D6 -> 0.057110723 | E6: ='Raw Data'!E14/'Raw Data'!E6 -> 0.059060821 | F6: ='Raw Data'!F14/'Raw Data'!F6 -> 0.058799704 | G6: ='Raw Data'!G14/'Raw Data'!G6 -> 0.056262443 | H6: Net Profit Margin remained relatively stable during FY2022–FY2026, ranging between 5.54% and 5.91%. This indicates that L&T was able to maintain a fairly consistent level of net profitability despite fluctuations in sales, expenses and other income.
A7: Return on Equity (ROE) (%) | B7: Net Profit ÷ Equity | C7: ='Raw Data'!C14/'Financial Ratios'!C29 -> 0.10520054 | D7: ='Raw Data'!D14/'Financial Ratios'!D29 -> 0.11721924 | E7: ='Raw Data'!E14/'Financial Ratios'!E29 -> 0.15121845 | F7: ='Raw Data'!F14/'Financial Ratios'!F29 -> 0.15398103 | G7: ='Raw Data'!G14/'Financial Ratios'!G29 -> 0.14716826 | H7: ROE increased from 10.52% in FY2022 to 14.72% in FY2026, indicating an overall improvement in the company's ability to generate profit from shareholders' equity. Although ROE declined slightly from 15.40% in FY2025, it remained significantly higher than the FY2022 level.
A8: Return on Assets (ROA) (%) | B8: Net Profit ÷ Total Assets | C8: ='Raw Data'!C14/'Raw Data'!C28 -> 0.027174206 | D8: ='Raw Data'!D14/'Raw Data'!D28 -> 0.031756218 | E8: ='Raw Data'!E14/'Raw Data'!E28 -> 0.038454123 | F8: ='Raw Data'!F14/'Raw Data'!F28 -> 0.039663812 | G8: ='Raw Data'!G14/'Raw Data'!G28 -> 0.03555394 | H8: ROA increased from 2.72% in FY2022 to 3.56% in FY2026, indicating an overall improvement in the company's ability to generate net profit from its asset base. The ratio peaked at 3.97% in FY2025 before declining slightly in FY2026.
A9: Return on Capital Employed (ROCE) (%) | B9: EBIT ÷ Capital Employed | C9: =C30/C31 -> 0.12831111 | D9: =D30/D31 -> 0.14314333 | E9: =E30/E31 -> 0.16632804 | F9: =F30/F31 -> 0.16353999 | G9: =G30/G31 -> 0.1720564 | H9: ROCE increased from 12.83% in FY2022 to 17.21% in FY2026, indicating an overall improvement in L&T's ability to generate operating returns from the capital employed in the business. This suggests improved efficiency in utilizing both shareholders' funds and borrowed capital.
A11: LEVERAGE RATIOS
A12: Debt-to-Equity Ratio | B12: Borrowings ÷ Equity | C12: ='Raw Data'!C20/'Financial Ratios'!C29 -> 1.5230147 | D12: ='Raw Data'!D20/'Financial Ratios'!D29 -> 1.3506763 | E12: ='Raw Data'!E20/'Financial Ratios'!E29 -> 1.3469574 | F12: ='Raw Data'!F20/'Financial Ratios'!F29 -> 1.3558764 | G12: ='Raw Data'!G20/'Financial Ratios'!G29 -> 1.1482919 | H12: The Debt-to-Equity Ratio declined from 1.52x in FY2022 to 1.15x in FY2026, indicating a reduction in the company's dependence on borrowings relative to shareholders' equity. The lower ratio in FY2026 suggests an improvement in the company's overall financial leverage.
A13: Interest Coverage Ratio | B13: EBIT ÷ Interest | C13: =C30/'Raw Data'!C11 -> 2.8887881 | D13: =D30/'Raw Data'!D11 -> 3.1821408 | E13: =E30/'Raw Data'!E11 -> 3.5440504 | F13: =F30/'Raw Data'!F11 -> 3.7909908 | G13: =G30/'Raw Data'!G11 -> 4.0171779 | H13: The Interest Coverage Ratio improved consistently from 2.89x in FY2022 to 4.02x in FY2026. This indicates that L&T's ability to cover its interest expenses from operating earnings has strengthened, reducing the pressure of interest costs on the company.
A14: Debt Ratio | B14: Borrowings ÷ Total Assets | C14: ='Raw Data'!C20/'Raw Data'!C28 -> 0.39340784 | D14: ='Raw Data'!D20/'Raw Data'!D28 -> 0.36591578 | E14: ='Raw Data'!E20/'Raw Data'!E28 -> 0.34252479 | F14: ='Raw Data'!F20/'Raw Data'!F28 -> 0.34925877 | G14: ='Raw Data'!G20/'Raw Data'!G28 -> 0.2774124 | H14: The Debt Ratio declined from 39.34% in FY2022 to 27.74% in FY2026, indicating that the proportion of total assets financed through borrowings has decreased. Although the ratio remained above 30% during FY2022–FY2025, it fell below 30% in FY2026, indicating lower financial leverage.
A16: EFFICIENCY RATIOS
A17: Asset Turnover Ratio | B17: Sales ÷ Total Assets | C17: ='Raw Data'!C6/'Raw Data'!C28 -> 0.49061924 | D17: ='Raw Data'!D6/'Raw Data'!D28 -> 0.55604651 | E17: ='Raw Data'!E6/'Raw Data'!E28 -> 0.6510936 | F17: ='Raw Data'!F6/'Raw Data'!F28 -> 0.67455802 | G17: ='Raw Data'!G6/'Raw Data'!G28 -> 0.63193026 | H17: The Asset Turnover Ratio increased from 0.49x in FY2022 to 0.63x in FY2026, indicating an overall improvement in the company's ability to generate sales from its asset base. However, the ratio declined slightly from 0.67x in FY2025 to 0.63x in FY2026.
A18: Fixed Asset Turnover Ratio | B18: Sales ÷ Net Block | C18: ='Raw Data'!C6/'Raw Data'!C24 -> 3.6446896 | D18: ='Raw Data'!D6/'Raw Data'!D24 -> 4.2996342 | E18: ='Raw Data'!E6/'Raw Data'!E24 -> 5.1464909 | F18: ='Raw Data'!F6/'Raw Data'!F24 -> 5.8048312 | G18: ='Raw Data'!G6/'Raw Data'!G24 -> 9.2615153 | H18: The Fixed Asset Turnover Ratio increased significantly from 3.64x in FY2022 to 9.26x in FY2026, indicating that the company generated substantially more sales relative to its net fixed asset base. However, the sharp increase in FY2026 was also influenced by a significant reduction in net block, so the increase should be interpreted with caution.
A19: Debtor Days | B19: Receivables ÷ Sales x 365 | C19: ='Raw Data'!C34/'Raw Data'!C6*365 -> 107.59468 | D19: ='Raw Data'!D34/'Raw Data'!D6*365 -> 89.052831 | E19: ='Raw Data'!E34/'Raw Data'!E6*365 -> 80.508175 | F19: ='Raw Data'!F34/'Raw Data'!F6*365 -> 76.663481 | G19: ='Raw Data'!G34/'Raw Data'!G6*365 -> 77.19601 | H19: Debtor Days declined significantly from 107.59 days in FY2022 to 77.20 days in FY2026, indicating an overall improvement in the collection of receivables and working capital efficiency. Although the ratio increased slightly in FY2026 compared with FY2025, the overall trend remains positive.
A21: CASH FLOW RATIOS
A22: Operating Cash Flow to Net Profit | B22: Cash from Operating Activity ÷ Net Profit | C22: ='Raw Data'!C41/'Raw Data'!C14 -> 2.210503 | D22: ='Raw Data'!D41/'Raw Data'!D14 -> 2.1753003 | E22: ='Raw Data'!E41/'Raw Data'!E14 -> 1.3987385 | F22: ='Raw Data'!F41/'Raw Data'!F14 -> 0.60858436 | G22: ='Raw Data'!G41/'Raw Data'!G14 -> 1.0408468 | H22: The Operating Cash Flow to Net Profit Ratio showed significant fluctuations during FY2022–FY2026. It declined from 2.21x in FY2022 to 0.61x in FY2025 before recovering to 1.04x in FY2026. The FY2026 ratio indicates that operating cash flow was slightly higher than reported net profit, although the overall trend shows volatility in cash conversion.
A23: Operating Cash Flow Margin | B23: Cash from Operating Activity ÷ Sales | C23: ='Raw Data'!C41/'Raw Data'!C6 -> 0.12243438 | D23: ='Raw Data'!D41/'Raw Data'!D6 -> 0.12423297 | E23: ='Raw Data'!E41/'Raw Data'!E6 -> 0.082610644 | F23: ='Raw Data'!F41/'Raw Data'!F6 -> 0.03578458 | G23: ='Raw Data'!G41/'Raw Data'!G6 -> 0.058560586 | H23: Operating Cash Flow Margin was relatively strong at around 12% during FY2022–FY2023 but declined to 3.58% in FY2025. It recovered to 5.86% in FY2026, indicating an improvement in operating cash generation, although the margin remained below its FY2022–FY2023 levels.
A25: MARKET/ SHAREHOLDER RATIOS
A26: EPS Growth | B26: (Current EPS - Prior EPS) ÷ Prior EPS | C26: =('Raw Data'!C15-'Raw Data'!B15)/'Raw Data'!B15 -> -0.25175566 | D26: =('Raw Data'!D15-'Raw Data'!C15)/'Raw Data'!C15 -> 0.20735917 | E26: =('Raw Data'!E15-'Raw Data'!D15)/'Raw Data'!D15 -> 0.27514611 | F26: =('Raw Data'!F15-'Raw Data'!E15)/'Raw Data'!E15 -> 0.15104649 | G26: =('Raw Data'!G15-'Raw Data'!F15)/'Raw Data'!F15 -> 0.069308734 | H26: EPS declined by 25.18% in FY2022 compared with FY2021. However, EPS growth recovered strongly thereafter, reaching 27.51% in FY2024. Growth remained positive in FY2025 and FY2026 at 15.10% and 6.93% respectively, indicating continued growth in earnings per share, although the growth rate has moderated in recent years.
A28: Helper Calculation
A29: Shareholder's Equity | B29: Equity Capital + Reserves | C29: ='Raw Data'!C18+'Raw Data'!C19 -> 82407.66 | D29: ='Raw Data'!D18+'Raw Data'!D19 -> 89325.95 | E29: ='Raw Data'!E18+'Raw Data'!E19 -> 86359.24 | F29: ='Raw Data'!F18+'Raw Data'!F19 -> 97655.6 | G29: ='Raw Data'!G18+'Raw Data'!G19 -> 109289.8
A30: EBIT | B30: Operating Profit + Other Income | C30: ='Raw Data'!C8+'Raw Data'!C9 -> 26677.9 | D30: ='Raw Data'!D8+'Raw Data'!D9 -> 30056.72 | E30: ='Raw Data'!E8+'Raw Data'!E9 -> 33711.61 | F30: ='Raw Data'!F8+'Raw Data'!F9 -> 37624.75 | G30: ='Raw Data'!G8+'Raw Data'!G9 -> 40396.5
A31: Capital Employed | B31: Shareholders' Equity + Borrowings | C31: ='Financial Ratios'!C29+'Raw Data'!C20 -> 207915.74 | D31: ='Financial Ratios'!D29+'Raw Data'!D20 -> 209976.39 | E31: ='Financial Ratios'!E29+'Raw Data'!E20 -> 202681.46 | F31: ='Financial Ratios'!F29+'Raw Data'!F20 -> 230064.52 | G31: ='Financial Ratios'!G29+'Raw Data'!G20 -> 234786.39
A33: EBIT for 2021 | B33: ='Raw Data'!B8+'Raw Data'!B9 -> 31571.49

Sheet DCF Valuation
A1: Financial Statement Analysis & Valuation – DCF Model (₹ Crores)
A3: Particulars | B3: FY2027 | C3: FY2028 | D3: FY2029 | E3: FY2030 | F3: FY2031 | G3: Remarks
A5: ASSUMPTIONS
A6: Assumptions | B6: Values | C6: Source/ Basis
A7: Revenue Growth | B7: =AVERAGE(B49:F49) -> 0.16057457 | C7: Average FY2022–FY2026 historical growth
A8: EBIT Margin | B8: =AVERAGE(B50:F50) -> 0.13841203 | C8: Average FY2022–FY2026 historical margin
A9: Tax Expense | B9: =AVERAGE(B51:F51) -> 0.26110561 | C9: Average FY2022–FY2026 effective tax rate
A10: Depreciation % | B10: =AVERAGE(B52:F52) -> 0.017194673 | C10: Average FY2022–FY2026 depreciation
A11: Capital Expenditure (CapEx) | B11: 0.025 | C11: Assumption:
A12: Working Capital % | B12: 0.1 | C12: Assumption:
A13: WACC | B13: 0.1 | C13: Assumption:
A14: Terminal Growth | B14: 0.04 | C14: Assumption:
A16: REVENUE PROJECTIONS
A17: Revenue | B17: ='Raw Data'!G6*(1+'DCF Valuation'!B7) -> 331778.51 | C17: ='DCF Valuation'!B17*(1+'DCF Valuation'!B7) -> 385053.7 | D17: =C17*(1+B7) -> 446883.54 | E17: =D17*(1+B7) -> 518641.67 | F17: =E17*(1+B7) -> 601922.33
A18: Growth Rate | B18: =B17/'Raw Data'!G6-1 -> 0.16057457 | C18: =C17/B17-1 -> 0.16057457 | D18: =D17/C17-1 -> 0.16057457 | E18: =E17/D17-1 -> 0.16057457 | F18: =F17/E17-1 -> 0.16057457
A20: FREE CASH FLOW
A21: Revenue | B21: =B17 -> 331778.51 | C21: =C17 -> 385053.7 | D21: =D17 -> 446883.54 | E21: =E17 -> 518641.67 | F21: =F17 -> 601922.33
A22: EBIT | B22: =B21*B8 -> 45922.137 | C22: =C21*B8 -> 53296.064 | D22: =D21*B8 -> 61854.057 | E22: =E21*B8 -> 71786.246 | F22: =F21*B8 -> 83313.291
A23: Tax | B23: =B22*B9 -> 11990.528 | C23: =C22*B9 -> 13915.901 | D23: =D22*B9 -> 16150.441 | E23: =E22*B9 -> 18743.791 | F23: =F22*B9 -> 21753.568
A24: NOPAT | B24: =B22-B23 -> 33931.609 | C24: =C22-C23 -> 39380.163 | D24: =D22-D23 -> 45703.616 | E24: =E22-E23 -> 53042.454 | F24: =F22-F23 -> 61559.723
A25: Depreciation | B25: =B21*B10 -> 5704.823 | C25: =C21*B10 -> 6620.8725 | D25: =D21*B10 -> 7684.0163 | E25: =E21*B10 -> 8917.8739 | F25: =F21*B10 -> 10349.858
A26: Capex | B26: =B21*B11 -> 8294.4628 | C26: =C21*B11 -> 9626.3426 | D26: =D21*B11 -> 11172.088 | E26: =E21*B11 -> 12966.042 | F26: =F21*B11 -> 15048.058
A27: Change in Working Capital | B27: =B21*B12-'Raw Data'!G30 -> -99053.889 | C27: =C21*B12-B21*B12 -> 5327.5191 | D27: =D21*B12-C21*B12 -> 6182.9832 | E27: =E21*B12-D21*B12 -> 7175.8131 | F27: =F21*B12-E21*B12 -> 8328.0662
A28: Free Cash Flow | B28: =B24+B25-B26-B27 -> 130395.86 | C28: =C24+C25-C26-C27 -> 31047.174 | D28: =D24+D25-D26-D27 -> 36032.56 | E28: =E24+E25-E26-E27 -> 41818.473 | F28: =F24+F25-F26-F27 -> 48533.457
A30: DCF VALUATION
A31: Free Cash Flow | B31: =B28 -> 130395.86 | C31: =C28 -> 31047.174 | D31: =D28 -> 36032.56 | E31: =E28 -> 41818.473 | F31: =F28 -> 48533.457
A32: Discount Factor | B32: =1/(1+B13)^1 -> 0.90909091 | C32: =1/(1+B13)^2 -> 0.82644628 | D32: =1/(1+$B$13)^3 -> 0.7513148 | E32: =1/(1+$B$13)^4 -> 0.68301346 | F32: =1/(1+$B$13)^5 -> 0.62092132
A33: Present Value | B33: =B31*B32 -> 118541.69 | C33: =C31*C32 -> 25658.821 | D33: =D31*D32 -> 27071.796 | E33: =E31*E32 -> 28562.58 | F33: =F31*F32 -> 30135.458
A34: Terminal Value | B34: =F31*(1+$B$14)/($B$13-$B$14) -> 841246.58
A35: Present Value of Terminal Value | B35: =B34*F32 -> 522347.94
A36: Enterprise Value | B36: =SUM(B33:F33)+B35 -> 752318.28
A38: VALUATION SUMMARY
A39: Item | B39: Value
A40: Enterprise Value | B40: =B36 -> 752318.28
A41: Less: Net Debt | B41: ='Raw Data'!G20-'Raw Data'!G36 -> 104648.92
A42: Equity Value | B42: =B40-B41 -> 647669.36
A43: Shares Outstanding | B43: ='Raw Data'!G37 -> 1375632190
A44: Intrinsic Value per Share | B44: =B42*10000000/B43 -> 4708.158
A45: Current Market Price | B45: 4061
A46: Upside/ Downside | B46: =(B44-B45)/B45 -> 0.15935926
...

Sheet Sensitivity Analysis
A1: Financial Statement Analysis & Valuation - Sensitivity Analysis (Crores)
A2: Sensitivity analysis evaluates how changes in key DCF assumptions affect the estimated intrinsic value per share
A4: INTRINSIC VALUE PER SHARE | I4: Notes
A5: WACC/ Terminal Growth | B5: 0.03 | C5: 0.035 | D5: 0.04 | E5: 0.045 | F5: 0.05
A7: 0.08 | B7: =(('DCF Valuation'!$B$31/(1+$A7)^1+'DCF Valuation'!$C$31/(1+$A7)^2+'DCF Valuation'!$D$31/(1+$A7)^3+'DCF Valuation'!$E$31/(1+$A7)^4+'DCF Valuation'!$F$31/(1+$A7)^5+(('DCF Valuation'!$F$31*(1+B$5))/($A7-B$5))/(1+$A7)^5)-'DCF Valuation'!$B$41)*10000000/'DCF Valuation'!$B$43 -> 5928.3169 | C7: =(('DCF Valuation'!$B$31/(1+$A7)^1+'DCF Valuation'!$C$31/(1+$A7)^2+'DCF Valuation'!$D$31/(1+$A7)^3+'DCF Valuation'!$E$31/(1+$A7)^4+'DCF Valuation'!$F$31/(1+$A7)^5+(('DCF Valuation'!$F$31*(1+C$5))/($A7-C$5))/(1+$A7)^5)-'DCF Valuation'!$B$41)*10000000/'DCF Valuation'!$B$43 -> 6504.594 | D7: =(('DCF Valuation'!$B$31/(1+$A7)^1+'DCF Valuation'!$C$31/(1+$A7)^2+'DCF Valuation'!$D$31/(1+$A7)^3+'DCF Valuation'!$E$31/(1+$A7)^4+'DCF Valuation'!$F$31/(1+$A7)^5+(('DCF Valuation'!$F$31*(1+D$5))/($A7-D$5))/(1+$A7)^5)-'DCF Valuation'!$B$41)*10000000/'DCF Valuation'!$B$43 -> 7224.9404 | E7: =(('DCF Valuation'!$B$31/(1+$A7)^1+'DCF Valuation'!$C$31/(1+$A7)^2+'DCF Valuation'!$D$31/(1+$A7)^3+'DCF Valuation'!$E$31/(1+$A7)^4+'DCF Valuation'!$F$31/(1+$A7)^5+(('DCF Valuation'!$F$31*(1+E$5))/($A7-E$5))/(1+$A7)^5)-'DCF Valuation'!$B$41)*10000000/'DCF Valuation'!$B$43 -> 8151.1 | F7: =(('DCF Valuation'!$B$31/(1+$A7)^1+'DCF Valuation'!$C$31/(1+$A7)^2+'DCF Valuation'!$D$31/(1+$A7)^3+'DCF Valuation'!$E$31/(1+$A7)^4+'DCF Valuation'!$F$31/(1+$A7)^5+(('DCF Valuation'!$F$31*(1+F$5))/($A7-F$5))/(1+$A7)^5)-'DCF Valuation'!$B$41)*10000000/'DCF Valuation'!$B$43 -> 9385.9795
A8: 0.09 | B8: =(('DCF Valuation'!$B$31/(1+$A8)^1+'DCF Valuation'!$C$31/(1+$A8)^2+'DCF Valuation'!$D$31/(1+$A8)^3+'DCF Valuation'!$E$31/(1+$A8)^4+'DCF Valuation'!$F$31/(1+$A8)^5+(('DCF Valuation'!$F$31*(1+B$5))/($A8-B$5))/(1+$A8)^5)-'DCF Valuation'!$B$41)*10000000/'DCF Valuation'!$B$43 -> 4882.1178 | C8: =(('DCF Valuation'!$B$31/(1+$A8)^1+'DCF Valuation'!$C$31/(1+$A8)^2+'DCF Valuation'!$D$31/(1+$A8)^3+'DCF Valuation'!$E$31/(1+$A8)^4+'DCF Valuation'!$F$31/(1+$A8)^5+(('DCF Valuation'!$F$31*(1+C$5))/($A8-C$5))/(1+$A8)^5)-'DCF Valuation'!$B$41)*10000000/'DCF Valuation'!$B$43 -> 5260.8123 | D8: =(('DCF Valuation'!$B$31/(1+$A8)^1+'DCF Valuation'!$C$31/(1+$A8)^2+'DCF Valuation'!$D$31/(1+$A8)^3+'DCF Valuation'!$E$31/(1+$A8)^4+'DCF Valuation'!$F$31/(1+$A8)^5+(('DCF Valuation'!$F$31*(1+D$5))/($A8-D$5))/(1+$A8)^5)-'DCF Valuation'!$B$41)*10000000/'DCF Valuation'!$B$43 -> 5715.2456 | E8: =(('DCF Valuation'!$B$31/(1+$A8)^1+'DCF Valuation'!$C$31/(1+$A8)^2+'DCF Valuation'!$D$31/(1+$A8)^3+'DCF Valuation'!$E$31/(1+$A8)^4+'DCF Valuation'!$F$31/(1+$A8)^5+(('DCF Valuation'!$F$31*(1+E$5))/($A8-E$5))/(1+$A8)^5)-'DCF Valuation'!$B$41)*10000000/'DCF Valuation'!$B$43 -> 6270.6642 | F8: =(('DCF Valuation'!$B$31/(1+$A8)^1+'DCF Valuation'!$C$31/(1+$A8)^2+'DCF Valuation'!$D$31/(1+$A8)^3+'DCF Valuation'!$E$31/(1+$A8)^4+'DCF Valuation'!$F$31/(1+$A8)^5+(('DCF Valuation'!$F$31*(1+F$5))/($A8-F$5))/(1+$A8)^5)-'DCF Valuation'!$B$41)*10000000/'DCF Valuation'!$B$43 -> 6964.9374
A9: 0.1 | B9: =(('DCF Valuation'!$B$31/(1+$A9)^1+'DCF Valuation'!$C$31/(1+$A9)^2+'DCF Valuation'!$D$31/(1+$A9)^3+'DCF Valuation'!$E$31/(1+$A9)^4+'DCF Valuation'!$F$31/(1+$A9)^5+(('DCF Valuation'!$F$31*(1+B$5))/($A9-B$5))/(1+$A9)^5)-'DCF Valuation'!$B$41)*10000000/'DCF Valuation'!$B$43 -> 4134.413 | C9: =(('DCF Valuation'!$B$31/(1+$A9)^1+'DCF Valuation'!$C$31/(1+$A9)^2+'DCF Valuation'!$D$31/(1+$A9)^3+'DCF Valuation'!$E$31/(1+$A9)^4+'DCF Valuation'!$F$31/(1+$A9)^5+(('DCF Valuation'!$F$31*(1+C$5))/($A9-C$5))/(1+$A9)^5)-'DCF Valuation'!$B$41)*10000000/'DCF Valuation'!$B$43 -> 4399.2184 | D9: =(('DCF Valuation'!$B$31/(1+$A9)^1+'DCF Valuation'!$C$31/(1+$A9)^2+'DCF Valuation'!$D$31/(1+$A9)^3+'DCF Valuation'!$E$31/(1+$A9)^4+'DCF Valuation'!$F$31/(1+$A9)^5+(('DCF Valuation'!$F$31*(1+D$5))/($A9-D$5))/(1+$A9)^5)-'DCF Valuation'!$B$41)*10000000/'DCF Valuation'!$B$43 -> 4708.158 | E9: =(('DCF Valuation'!$B$31/(1+$A9)^1+'DCF Valuation'!$C$31/(1+$A9)^2+'DCF Valuation'!$D$31/(1+$A9)^3+'DCF Valuation'!$E$31/(1+$A9)^4+'DCF Valuation'!$F$31/(1+$A9)^5+(('DCF Valuation'!$F$31*(1+E$5))/($A9-E$5))/(1+$A9)^5)-'DCF Valuation'!$B$41)*10000000/'DCF Valuation'!$B$43 -> 5073.2684 | F9: =(('DCF Valuation'!$B$31/(1+$A9)^1+'DCF Valuation'!$C$31/(1+$A9)^2+'DCF Valuation'!$D$31/(1+$A9)^3+'DCF Valuation'!$E$31/(1+$A9)^4+'DCF Valuation'!$F$31/(1+$A9)^5+(('DCF Valuation'!$F$31*(1+F$5))/($A9-F$5))/(1+$A9)^5)-'DCF Valuation'!$B$41)*10000000/'DCF Valuation'!$B$43 -> 5511.4009
A10: 0.11 | B10: =(('DCF Valuation'!$B$31/(1+$A10)^1+'DCF Valuation'!$C$31/(1+$A10)^2+'DCF Valuation'!$D$31/(1+$A10)^3+'DCF Valuation'!$E$31/(1+$A10)^4+'DCF Valuation'!$F$31/(1+$A10)^5+(('DCF Valuation'!$F$31*(1+B$5))/($A10-B$5))/(1+$A10)^5)-'DCF Valuation'!$B$41)*10000000/'DCF Valuation'!$B$43 -> 3573.2543 | C10: =(('DCF Valuation'!$B$31/(1+$A10)^1+'DCF Valuation'!$C$31/(1+$A10)^2+'DCF Valuation'!$D$31/(1+$A10)^3+'DCF Valuation'!$E$31/(1+$A10)^4+'DCF Valuation'!$F$31/(1+$A10)^5+(('DCF Valuation'!$F$31*(1+C$5))/($A10-C$5))/(1+$A10)^5)-'DCF Valuation'!$B$41)*10000000/'DCF Valuation'!$B$43 -> 3766.9258 | D10: =(('DCF Valuation'!$B$31/(1+$A10)^1+'DCF Valuation'!$C$31/(1+$A10)^2+'DCF Valuation'!$D$31/(1+$A10)^3+'DCF Valuation'!$E$31/(1+$A10)^4+'DCF Valuation'!$F$31/(1+$A10)^5+(('DCF Valuation'!$F$31*(1+D$5))/($A10-D$5))/(1+$A10)^5)-'DCF Valuation'!$B$41)*10000000/'DCF Valuation'!$B$43 -> 3988.2647 | E10: =(('DCF Valuation'!$B$31/(1+$A10)^1+'DCF Valuation'!$C$31/(1+$A10)^2+'DCF Valuation'!$D$31/(1+$A10)^3+'DCF Valuation'!$E$31/(1+$A10)^4+'DCF Valuation'!$F$31/(1+$A10)^5+(('DCF Valuation'!$F$31*(1+E$5))/($A10-E$5))/(1+$A10)^5)-'DCF Valuation'!$B$41)*10000000/'DCF Valuation'!$B$43 -> 4243.6557 | F10: =(('DCF Valuation'!$B$31/(1+$A10)^1+'DCF Valuation'!$C$31/(1+$A10)^2+'DCF Valuation'!$D$31/(1+$A10)^3+'DCF Valuation'!$E$31/(1+$A10)^4+'DCF Valuation'!$F$31/(1+$A10)^5+(('DCF Valuation'!$F$31*(1+F$5))/($A10-F$5))/(1+$A10)^5)-'DCF Valuation'!$B$41)*10000000/'DCF Valuation'!$B$43 -> 4541.6119
A11: 0.12 | B11: =(('DCF Valuation'!$B$31/(1+$A11)^1+'DCF Valuation'!$C$31/(1+$A11)^2+'DCF Valuation'!$D$31/(1+$A11)^3+'DCF Valuation'!$E$31/(1+$A11)^4+'DCF Valuation'!$F$31/(1+$A11)^5+(('DCF Valuation'!$F$31*(1+B$5))/($A11-B$5))/(1+$A11)^5)-'DCF Valuation'!$B$41)*10000000/'DCF Valuation'!$B$43 -> 3136.4496 | C11: =(('DCF Valuation'!$B$31/(1+$A11)^1+'DCF Valuation'!$C$31/(1+$A11)^2+'DCF Valuation'!$D$31/(1+$A11)^3+'DCF Valuation'!$E$31/(1+$A11)^4+'DCF Valuation'!$F$31/(1+$A11)^5+(('DCF Valuation'!$F$31*(1+C$5))/($A11-C$5))/(1+$A11)^5)-'DCF Valuation'!$B$41)*10000000/'DCF Valuation'!$B$43 -> 3282.9961 | D11: =(('DCF Valuation'!$B$31/(1+$A11)^1+'DCF Valuation'!$C$31/(1+$A11)^2+'DCF Valuation'!$D$31/(1+$A11)^3+'DCF Valuation'!$E$31/(1+$A11)^4+'DCF Valuation'!$F$31/(1+$A11)^5+(('DCF Valuation'!$F$31*(1+D$5))/($A11-D$5))/(1+$A11)^5)-'DCF Valuation'!$B$41)*10000000/'DCF Valuation'!$B$43 -> 3447.8609 | E11: =(('DCF Valuation'!$B$31/(1+$A11)^1+'DCF Valuation'!$C$31/(1+$A11)^2+'DCF Valuation'!$D$31/(1+$A11)^3+'DCF Valuation'!$E$31/(1+$A11)^4+'DCF Valuation'!$F$31/(1+$A11)^5+(('DCF Valuation'!$F$31*(1+E$5))/($A11-E$5))/(1+$A11)^5)-'DCF Valuation'!$B$41)*10000000/'DCF Valuation'!$B$43 -> 3634.7077 | F11: =(('DCF Valuation'!$B$31/(1+$A11)^1+'DCF Valuation'!$C$31/(1+$A11)^2+'DCF Valuation'!$D$31/(1+$A11)^3+'DCF Valuation'!$E$31/(1+$A11)^4+'DCF Valuation'!$F$31/(1+$A11)^5+(('DCF Valuation'!$F$31*(1+F$5))/($A11-F$5))/(1+$A11)^5)-'DCF Valuation'!$B$41)*10000000/'DCF Valuation'!$B$43 -> 3848.2468
A13: Interpretation
A14: Higher WACC generally reduces the present value of future cash flows, while higher terminal growth generally increases the estimated intrinsic value per share.
A16: Based on the DCF model, L&T's estimated intrinsic value per share is ₹4,802.43 under the base-case assumptions of 10% WACC and 4% terminal growth. The sensitivity analysis indicates that the valuation is positively affected by higher terminal growth and negatively affected by higher WACC.

Sheet Charts
A1: Financial Statement Analysis & Valuation - Charts
R3: J | S3: K
R4: Year | S4: Revenue
R5: FY2022 | S5: ='Raw Data'!B6 -> 135979.03
R6: FY2023 | S6: ='Raw Data'!C6 -> 156521.23
R7: FY2024 | S7: ='Raw Data'!D6 -> 183340.7
R8: FY2025 | S8: ='Raw Data'!E6 -> 221112.91
R9: FY2026 | S9: ='Raw Data'!F6 -> 255734.45
R11: Year | S11: Operating Profit | T11: Net Profit
R12: FY2022 | S12: ='Raw Data'!B8 -> 23460.24 | T12: ='Raw Data'!B14 -> 11582.93
R13: FY2023 | S13: ='Raw Data'!C8 -> 24313.89 | T13: ='Raw Data'!C14 -> 8669.33
R14: FY2024 | S14: ='Raw Data'!D8 -> 27166.02 | T14: ='Raw Data'!D14 -> 10470.72
R15: FY2025 | S15: ='Raw Data'!E8 -> 28758.12 | T15: ='Raw Data'!E14 -> 13059.11
R16: FY2026 | S16: ='Raw Data'!F8 -> 34426.9 | T16: ='Raw Data'!F14 -> 15037.11
R18: Year | S18: OPM | T18: NPM
R19: FY2022 | S19: ='Financial Ratios'!C5 -> 0.15533925 | T19: ='Financial Ratios'!C6 -> 0.055387566
R20: FY2023 | S20: ='Financial Ratios'!D5 -> 0.14817234 | T20: ='Financial Ratios'!D6 -> 0.057110723
R21: FY2024 | S21: ='Financial Ratios'!E5 -> 0.13006079 | T21: ='Financial Ratios'!E6 -> 0.059060821
R22: FY2025 | S22: ='Financial Ratios'!F5 -> 0.13461972 | T22: ='Financial Ratios'!F6 -> 0.058799704
R23: FY2026 | S23: ='Financial Ratios'!G5 -> 0.12386805 | T23: ='Financial Ratios'!G6 -> 0.056262443
R25: Year | S25: Debt-to-Equity | T25: Interest Coverage
R26: FY2022 | S26: ='Financial Ratios'!C12 -> 1.5230147 | T26: ='Financial Ratios'!C13 -> 2.8887881
R27: FY2023 | S27: ='Financial Ratios'!D12 -> 1.3506763 | T27: ='Financial Ratios'!D13 -> 3.1821408
R28: FY2024 | S28: ='Financial Ratios'!E12 -> 1.3469574 | T28: ='Financial Ratios'!E13 -> 3.5440504
R29: FY2025 | S29: ='Financial Ratios'!F12 -> 1.3558764 | T29: ='Financial Ratios'!F13 -> 3.7909908
R30: FY2026 | S30: ='Financial Ratios'!G12 -> 1.1482919 | T30: ='Financial Ratios'!G13 -> 4.0171779
R32: Valuation | S32: ₹/Share
R33: DCF Intrinsic Value | S33: ='DCF Valuation'!B44 -> 4708.158
R34: Current Market Price | S34: ='DCF Valuation'!B45 -> 4061
